2021-07-19 14:47:00,843 ERROR frappe Could not take error snapshot: characters_written
Site: atualli.local
Form Dict: {'items': '["/assets/frappe/dist/js/build_events.bundle.HQFRKT43.js"]', 'cmd': 'frappe.client.get_js'}
Traceback (most recent call last):
  File "/data/bench/apps/frappe/frappe/app.py", line 66, in application
    response = frappe.api.handle()
  File "/data/bench/apps/frappe/frappe/api.py", line 54, in handle
    return frappe.handler.handle()
  File "/data/bench/apps/frappe/frappe/handler.py", line 29, in handle
    data = execute_cmd(cmd)
  File "/data/bench/apps/frappe/frappe/handler.py", line 65, in execute_cmd
    return frappe.call(method, **frappe.form_dict)
  File "/data/bench/apps/frappe/frappe/__init__.py", line 1174, in call
    return fn(*args, **newargs)
  File "/data/bench/apps/frappe/frappe/client.py", line 330, in get_js
    with open(contentpath, "r") as srcfile:
FileNotFoundError: [Errno 2] No such file or directory: './assets/frappe/dist/js/build_events.bundle.HQFRKT43.js'

During handling of the above exception, another exception occurred:

Traceback (most recent call last):
  File "/data/bench/apps/frappe/frappe/utils/error.py", line 36, in make_error_snapshot
    snapshot = get_snapshot(exception)
  File "/data/bench/apps/frappe/frappe/utils/error.py", line 127, in get_snapshot
    value = pydoc.text.repr(getattr(evalue, name))
AttributeError: characters_written
2021-07-19 23:46:37,667 ERROR frappe New Exception collected with id: 2021-07-19 23:46:37.581785-127.0.0.1-594
Site: atualli.local
Form Dict: {'sid': '09d4029474952b484fc48c8bd984fdec83faf5dd269fe1567e2fecff', 'doctype': 'Pre_Service_Form', 'docname': 'new-pre_service_form-1', 'cmd': 'frappe.realtime.can_subscribe_doc'}
2021-07-19 23:46:56,211 ERROR frappe New Exception collected with id: 2021-07-19 23:46:56.205622-127.0.0.1-b45
Site: atualli.local
Form Dict: {'sid': '09d4029474952b484fc48c8bd984fdec83faf5dd269fe1567e2fecff', 'doctype': 'Pre_Service_Form', 'docname': 'new-pre_service_form-1', 'cmd': 'frappe.realtime.can_subscribe_doc'}
2021-07-19 23:50:03,050 ERROR frappe New Exception collected with id: 2021-07-19 23:50:03.043308-127.0.0.1-5bd
Site: atualli.local
Form Dict: {'sid': '09d4029474952b484fc48c8bd984fdec83faf5dd269fe1567e2fecff', 'doctype': 'Pre_Service_Form', 'docname': 'new-pre_service_form-1', 'cmd': 'frappe.realtime.can_subscribe_doc'}
2021-07-19 23:50:41,653 ERROR frappe Could not take error snapshot: ('EOF in multi-line string', (1, 23))
Site: atualli.local
Form Dict: {'user': 'maensfslk@hotmail.com', 'date': '2021-01-01', 'cmd': 'frappe.desk.page.user_profile.user_profile.get_energy_points_heatmap_data'}
Traceback (most recent call last):
  File "/data/bench/apps/frappe/frappe/app.py", line 66, in application
    response = frappe.api.handle()
  File "/data/bench/apps/frappe/frappe/api.py", line 54, in handle
    return frappe.handler.handle()
  File "/data/bench/apps/frappe/frappe/handler.py", line 29, in handle
    data = execute_cmd(cmd)
  File "/data/bench/apps/frappe/frappe/handler.py", line 65, in execute_cmd
    return frappe.call(method, **frappe.form_dict)
  File "/data/bench/apps/frappe/frappe/__init__.py", line 1174, in call
    return fn(*args, **newargs)
  File "/data/bench/apps/frappe/frappe/desk/page/user_profile/user_profile.py", line 20, in get_energy_points_heatmap_data
    order by creation asc""".format(date = date), user))
  File "/data/bench/apps/frappe/frappe/database/database.py", line 136, in sql
    self._cursor.execute(query, values)
  File "/data/bench/env/lib/python3.6/site-packages/pymysql/cursors.py", line 148, in execute
    result = self._query(query)
  File "/data/bench/env/lib/python3.6/site-packages/pymysql/cursors.py", line 310, in _query
    conn.query(q)
  File "/data/bench/env/lib/python3.6/site-packages/pymysql/connections.py", line 548, in query
    self._affected_rows = self._read_query_result(unbuffered=unbuffered)
  File "/data/bench/env/lib/python3.6/site-packages/pymysql/connections.py", line 775, in _read_query_result
    result.read()
  File "/data/bench/env/lib/python3.6/site-packages/pymysql/connections.py", line 1156, in read
    first_packet = self.connection._read_packet()
  File "/data/bench/env/lib/python3.6/site-packages/pymysql/connections.py", line 725, in _read_packet
    packet.raise_for_error()
  File "/data/bench/env/lib/python3.6/site-packages/pymysql/protocol.py", line 221, in raise_for_error
    err.raise_mysql_exception(self._data)
  File "/data/bench/env/lib/python3.6/site-packages/pymysql/err.py", line 143, in raise_mysql_exception
    raise errorclass(errno, errval)
pymysql.err.OperationalError: (1055, "Expression #1 of SELECT list is not in GROUP BY clause and contains nonaggregated column '_28185696d19449c5.tabEnergy Point Log.creation' which is not functionally dependent on columns in GROUP BY clause; this is incompatible with sql_mode=only_full_group_by")

During handling of the above exception, another exception occurred:

Traceback (most recent call last):
  File "/data/bench/apps/frappe/frappe/utils/error.py", line 36, in make_error_snapshot
    snapshot = get_snapshot(exception)
  File "/data/bench/apps/frappe/frappe/utils/error.py", line 92, in get_snapshot
    vars = cgitb.scanvars(reader, frame, locals)
  File "/usr/lib/python3.6/cgitb.py", line 83, in scanvars
    for ttype, token, start, end, line in tokenize.generate_tokens(reader):
  File "/usr/lib/python3.6/tokenize.py", line 530, in _tokenize
    raise TokenError("EOF in multi-line string", strstart)
tokenize.TokenError: ('EOF in multi-line string', (1, 23))
